2025-07-12 19:32:44,333 - root - ERROR - Enviando mensaje a persona-service en el canal default: {'from_service': 'auth-service', 'to_service': 'persona-service', 'channel': 'default', 'event_type': 'auth_user_register', 'message': {'id_usuario': 2, 'email': 'fabrizio.steinbach@gmail.com'}, 'message_id': '0ad6f71962fb457389f7edbf577091c6'}
2025-07-12 19:33:10,704 - app.routes.usuario.login_logout - INFO - → [ROUTE] Solicitud de login recibida
2025-07-12 19:33:10,714 - app.services.usuario_service - INFO - → Iniciando login de usuario
2025-07-12 19:33:10,938 - app.services.usuario_service - INFO - → Usuario 2 autenticado, generando tokens...
2025-07-12 19:33:10,974 - app.services.usuario_service - INFO - → Dispositivo no confiable, se envió mail de validación
2025-07-12 19:33:10,978 - app.routes.usuario.login_logout - INFO - → [ROUTE] Login procesado, status: ResponseStatus.PENDING, code: 403
2025-07-12 19:33:18,270 - root - ERROR - Excepción no manejada:
Traceback (most recent call last):
  File "/usr/local/lib/python3.10/site-packages/flask/app.py", line 917, in full_dispatch_request
    rv = self.dispatch_request()
  File "/usr/local/lib/python3.10/site-packages/flask/app.py", line 891, in dispatch_request
    self.raise_routing_exception(req)
  File "/usr/local/lib/python3.10/site-packages/flask/app.py", line 500, in raise_routing_exception
    raise request.routing_exception  # type: ignore[misc]
  File "/usr/local/lib/python3.10/site-packages/flask/ctx.py", line 362, in match_request
    result = self.url_adapter.match(return_rule=True)  # type: ignore
  File "/usr/local/lib/python3.10/site-packages/werkzeug/routing/map.py", line 629, in match
    raise NotFound() from None
werkzeug.exceptions.NotFound: 404 Not Found: The requested URL was not found on the server. If you entered the URL manually please check your spelling and try again.

2025-07-12 19:36:45,363 - root - ERROR - Enviando mensaje a persona-service en el canal default: {'from_service': 'auth-service', 'to_service': 'persona-service', 'channel': 'default', 'event_type': 'auth_user_register', 'message': {'id_usuario': 2, 'email': 'fabrizio.steinbach@gmail.com'}, 'message_id': '5c8707b97cd34b55bef794889d6d8ba4'}
2025-07-12 19:36:49,950 - app.routes.usuario.login_logout - INFO - → [ROUTE] Solicitud de login recibida
2025-07-12 19:36:49,958 - app.services.usuario_service - INFO - → Iniciando login de usuario
2025-07-12 19:36:50,425 - app.services.usuario_service - INFO - → Usuario 2 autenticado, generando tokens...
2025-07-12 19:36:50,991 - app.services.usuario_service - INFO - → Dispositivo no confiable, se envió mail de validación
2025-07-12 19:36:51,002 - app.routes.usuario.login_logout - INFO - → [ROUTE] Login procesado, status: ResponseStatus.PENDING, code: 403
2025-07-12 19:36:59,832 - root - ERROR - Excepción no manejada:
Traceback (most recent call last):
  File "/usr/local/lib/python3.10/site-packages/flask/app.py", line 917, in full_dispatch_request
    rv = self.dispatch_request()
  File "/usr/local/lib/python3.10/site-packages/flask/app.py", line 891, in dispatch_request
    self.raise_routing_exception(req)
  File "/usr/local/lib/python3.10/site-packages/flask/app.py", line 500, in raise_routing_exception
    raise request.routing_exception  # type: ignore[misc]
  File "/usr/local/lib/python3.10/site-packages/flask/ctx.py", line 362, in match_request
    result = self.url_adapter.match(return_rule=True)  # type: ignore
  File "/usr/local/lib/python3.10/site-packages/werkzeug/routing/map.py", line 629, in match
    raise NotFound() from None
werkzeug.exceptions.NotFound: 404 Not Found: The requested URL was not found on the server. If you entered the URL manually please check your spelling and try again.

2025-07-12 19:43:51,838 - root - ERROR - Enviando mensaje a persona-service en el canal default: {'from_service': 'auth-service', 'to_service': 'persona-service', 'channel': 'default', 'event_type': 'auth_user_register', 'message': {'id_usuario': 2, 'email': 'fabrizio@gmail.com'}, 'message_id': '4d3b9e42d0954749a76ce527ae86d241'}
2025-07-12 19:43:56,395 - app.routes.usuario.login_logout - INFO - → [ROUTE] Solicitud de login recibida
2025-07-12 19:43:56,409 - app.services.usuario_service - INFO - → Iniciando login de usuario
2025-07-12 19:43:56,619 - app.services.usuario_service - INFO - → Usuario 2 autenticado, generando tokens...
2025-07-12 19:43:56,637 - app.services.usuario_service - INFO - → Tokens generados correctamente
2025-07-12 19:43:56,642 - app.services.usuario_service - INFO - → Permisos almacenados en Redis
2025-07-12 19:43:56,645 - app.services.usuario_service - INFO - → Login finalizado para usuario 2
2025-07-12 19:43:56,658 - app.routes.usuario.login_logout - INFO - → [ROUTE] Login procesado, status: ResponseStatus.SUCCESS, code: 200
